Workbook

Sheet Summary
A1: Manual and Proposed System | Survey Entry | B1: Manual and Proposed System | Survey Entry | C1: Manual and Proposed System | Survey Entry | D1: Manual and Proposed System | Survey Entry | E1: Manual and Proposed System | Survey Entry | F1: Manual and Proposed System | Survey Entry | G1: Manual and Proposed System | Survey Entry | H1: Manual and Proposed System | Survey Entry
A3: Purpose: preserve each respondent's answers for an independent-samples comparison. Manual and system papers are separate groups. | B3: Purpose: preserve each respondent's answers for an independent-samples comparison. Manual and system papers are separate groups. | C3: Purpose: preserve each respondent's answers for an independent-samples comparison. Manual and system papers are separate groups. | D3: Purpose: preserve each respondent's answers for an independent-samples comparison. Manual and system papers are separate groups. | E3: Purpose: preserve each respondent's answers for an independent-samples comparison. Manual and system papers are separate groups. | F3: Purpose: preserve each respondent's answers for an independent-samples comparison. Manual and system papers are separate groups. | G3: Purpose: preserve each respondent's answers for an independent-samples comparison. Manual and system papers are separate groups. | H3: Purpose: preserve each respondent's answers for an independent-samples comparison. Manual and system papers are separate groups.
A5: 1. Count the papers. This template has 70 slots for each group; report any different actual count. | B5: 1. Count the papers. This template has 70 slots for each group; report any different actual count. | C5: 1. Count the papers. This template has 70 slots for each group; report any different actual count. | D5: 1. Count the papers. This template has 70 slots for each group; report any different actual count. | E5: 1. Count the papers. This template has 70 slots for each group; report any different actual count. | F5: 1. Count the papers. This template has 70 slots for each group; report any different actual count. | G5: 1. Count the papers. This template has 70 slots for each group; report any different actual count. | H5: 1. Count the papers. This template has 70 slots for each group; report any different actual count.
A6: 2. Label manual papers M01-M70 and system student papers S01-S70. No matching between groups is needed. | B6: 2. Label manual papers M01-M70 and system student papers S01-S70. No matching between groups is needed. | C6: 2. Label manual papers M01-M70 and system student papers S01-S70. No matching between groups is needed. | D6: 2. Label manual papers M01-M70 and system student papers S01-S70. No matching between groups is needed. | E6: 2. Label manual papers M01-M70 and system student papers S01-S70. No matching between groups is needed. | F6: 2. Label manual papers M01-M70 and system student papers S01-S70. No matching between groups is needed. | G6: 2. Label manual papers M01-M70 and system student papers S01-S70. No matching between groups is needed. | H6: 2. Label manual papers M01-M70 and system student papers S01-S70. No matching between groups is needed.
A7: 3. Enter each paper in its matching row on Manual or System. Use its original 1-4 response codes; enter only yellow cells. | B7: 3. Enter each paper in its matching row on Manual or System. Use its original 1-4 response codes; enter only yellow cells. | C7: 3. Enter each paper in its matching row on Manual or System. Use its original 1-4 response codes; enter only yellow cells. | D7: 3. Enter each paper in its matching row on Manual or System. Use its original 1-4 response codes; enter only yellow cells. | E7: 3. Enter each paper in its matching row on Manual or System. Use its original 1-4 response codes; enter only yellow cells. | F7: 3. Enter each paper in its matching row on Manual or System. Use its original 1-4 response codes; enter only yellow cells. | G7: 3. Enter each paper in its matching row on Manual or System. Use its original 1-4 response codes; enter only yellow cells. | H7: 3. Enter each paper in its matching row on Manual or System. Use its original 1-4 response codes; enter only yellow cells.
A8: 4. Check the section and question number using the key below each entry sheet. Do not replace an individual answer with an average. | B8: 4. Check the section and question number using the key below each entry sheet. Do not replace an individual answer with an average. | C8: 4. Check the section and question number using the key below each entry sheet. Do not replace an individual answer with an average. | D8: 4. Check the section and question number using the key below each entry sheet. Do not replace an individual answer with an average. | E8: 4. Check the section and question number using the key below each entry sheet. Do not replace an individual answer with an average. | F8: 4. Check the section and question number using the key below each entry sheet. Do not replace an individual answer with an average. | G8: 4. Check the section and question number using the key below each entry sheet. Do not replace an individual answer with an average. | H8: 4. Check the section and question number using the key below each entry sheet. Do not replace an individual answer with an average.
A9: 5. Have a second teammate check every entry against the paper, then enter their initials in Checked by. | B9: 5. Have a second teammate check every entry against the paper, then enter their initials in Checked by. | C9: 5. Have a second teammate check every entry against the paper, then enter their initials in Checked by. | D9: 5. Have a second teammate check every entry against the paper, then enter their initials in Checked by. | E9: 5. Have a second teammate check every entry against the paper, then enter their initials in Checked by. | F9: 5. Have a second teammate check every entry against the paper, then enter their initials in Checked by. | G9: 5. Have a second teammate check every entry against the paper, then enter their initials in Checked by. | H9: 5. Have a second teammate check every entry against the paper, then enter their initials in Checked by.
A10: 6. Resolve CHECK PAPER rows using the original paper. Keep genuinely missing answers blank and report them. | B10: 6. Resolve CHECK PAPER rows using the original paper. Keep genuinely missing answers blank and report them. | C10: 6. Resolve CHECK PAPER rows using the original paper. Keep genuinely missing answers blank and report them. | D10: 6. Resolve CHECK PAPER rows using the original paper. Keep genuinely missing answers blank and report them. | E10: 6. Resolve CHECK PAPER rows using the original paper. Keep genuinely missing answers blank and report them. | F10: 6. Resolve CHECK PAPER rows using the original paper. Keep genuinely missing answers blank and report them. | G10: 6. Resolve CHECK PAPER rows using the original paper. Keep genuinely missing answers blank and report them. | H10: 6. Resolve CHECK PAPER rows using the original paper. Keep genuinely missing answers blank and report them.
A12: Data readiness | B12: Manual | C12: System | D12: Expected per group
A13: Complete forms | B13: =COUNTIF(Manual!AF2:AF71,"Complete") -> 70 | C13: =COUNTIF(System!AF2:AF71,"Complete") -> 70 | D13: 70
A14: Rows needing a check | B14: =COUNTIF(Manual!AF2:AF71,"CHECK PAPER") -> 0 | C14: =COUNTIF(System!AF2:AF71,"CHECK PAPER") -> 0 | D14: 0
A15: Not entered | B15: =COUNTIF(Manual!AF2:AF71,"Not entered") -> 0 | C15: =COUNTIF(System!AF2:AF71,"Not entered") -> 0 | D15: 0
A17: The scores below appear only when all 70 forms in that group have valid answers. They are descriptive results, not the t-test. | B17: The scores below appear only when all 70 forms in that group have valid answers. They are descriptive results, not the t-test. | C17: The scores below appear only when all 70 forms in that group have valid answers. They are descriptive results, not the t-test. | D17: The scores below appear only when all 70 forms in that group have valid answers. They are descriptive results, not the t-test. | E17: The scores below appear only when all 70 forms in that group have valid answers. They are descriptive results, not the t-test. | F17: The scores below appear only when all 70 forms in that group have valid answers. They are descriptive results, not the t-test. | G17: The scores below appear only when all 70 forms in that group have valid answers. They are descriptive results, not the t-test. | H17: The scores below appear only when all 70 forms in that group have valid answers. They are descriptive results, not the t-test.
A19: Score | B19: Manual mean | C19: Manual sample SD | D19: System mean | E19: System sample SD
A20: Functional Suitability | B20: =IF($B$13=70,AVERAGE(Manual!Z2:Z71),"") -> 2.4828571 | C20: =IF($B$13=70,STDEV(Manual!Z2:Z71),"") -> 0.89862559 | D20: =IF($C$13=70,AVERAGE(System!Z2:Z71),"") -> 3.7628571 | E20: =IF($C$13=70,STDEV(System!Z2:Z71),"") -> 0.31813379
A21: Performance Efficiency | B21: =IF($B$13=70,AVERAGE(Manual!AA2:AA71),"") -> 1.9321429 | C21: =IF($B$13=70,STDEV(Manual!AA2:AA71),"") -> 0.91872768 | D21: =IF($C$13=70,AVERAGE(System!AA2:AA71),"") -> 3.7428571 | E21: =IF($C$13=70,STDEV(System!AA2:AA71),"") -> 0.36606859
A22: Usability | B22: =IF($B$13=70,AVERAGE(Manual!AB2:AB71),"") -> 2.6371429 | C22: =IF($B$13=70,STDEV(Manual!AB2:AB71),"") -> 0.85417499 | D22: =IF($C$13=70,AVERAGE(System!AB2:AB71),"") -> 3.74 | E22: =IF($C$13=70,STDEV(System!AB2:AB71),"") -> 0.32898615
A23: Reliability | B23: =IF($B$13=70,AVERAGE(Manual!AC2:AC71),"") -> 2.1828571 | C23: =IF($B$13=70,STDEV(Manual!AC2:AC71),"") -> 0.8524426 | D23: =IF($C$13=70,AVERAGE(System!AC2:AC71),"") -> 3.7114286 | E23: =IF($C$13=70,STDEV(System!AC2:AC71),"") -> 0.34830557
A24: Security | B24: =IF($B$13=70,AVERAGE(Manual!AD2:AD71),"") -> 2.1828571 | C24: =IF($B$13=70,STDEV(Manual!AD2:AD71),"") -> 0.8831714 | D24: =IF($C$13=70,AVERAGE(System!AD2:AD71),"") -> 3.7514286 | E24: =IF($C$13=70,STDEV(System!AD2:AD71),"") -> 0.34124362
A25: Overall score | B25: =IF($B$13=70,AVERAGE(Manual!AE2:AE71),"") -> 2.2835714 | C25: =IF($B$13=70,STDEV(Manual!AE2:AE71),"") -> 0.75261869 | D25: =IF($C$13=70,AVERAGE(System!AE2:AE71),"") -> 3.7417143 | E25: =IF($C$13=70,STDEV(System!AE2:AE71),"") -> 0.29021717
A27: Scoring: average each category's answers, then average the five category scores equally. Performance Efficiency has 4 items; each other category has 5. | B27: Scoring: average each category's answers, then average the five category scores equally. Performance Efficiency has 4 items; each other category has 5. | C27: Scoring: average each category's answers, then average the five category scores equally. Performance Efficiency has 4 items; each other category has 5. | D27: Scoring: average each category's answers, then average the five category scores equally. Performance Efficiency has 4 items; each other category has 5. | E27: Scoring: average each category's answers, then average the five category scores equally. Performance Efficiency has 4 items; each other category has 5. | F27: Scoring: average each category's answers, then average the five category scores equally. Performance Efficiency has 4 items; each other category has 5. | G27: Scoring: average each category's answers, then average the five category scores equally. Performance Efficiency has 4 items; each other category has 5. | H27: Scoring: average each category's answers, then average the five category scores equally. Performance Efficiency has 4 items; each other category has 5.
A29: Next analysis: a two-sided Welch independent-samples t-test on each person's overall score, after checking data entry, scoring direction, and comparable survey content. | B29: Next analysis: a two-sided Welch independent-samples t-test on each person's overall score, after checking data entry, scoring direction, and comparable survey content. | C29: Next analysis: a two-sided Welch independent-samples t-test on each person's overall score, after checking data entry, scoring direction, and comparable survey content. | D29: Next analysis: a two-sided Welch independent-samples t-test on each person's overall score, after checking data entry, scoring direction, and comparable survey content. | E29: Next analysis: a two-sided Welch independent-samples t-test on each person's overall score, after checking data entry, scoring direction, and comparable survey content. | F29: Next analysis: a two-sided Welch independent-samples t-test on each person's overall score, after checking data entry, scoring direction, and comparable survey content. | G29: Next analysis: a two-sided Welch independent-samples t-test on each person's overall score, after checking data entry, scoring direction, and comparable survey content. | H29: Next analysis: a two-sided Welch independent-samples t-test on each person's overall score, after checking data entry, scoring direction, and comparable survey content.
A31: Do not combine security-personnel or administrator forms with the student comparison. Keep those forms separate. | B31: Do not combine security-personnel or administrator forms with the student comparison. Keep those forms separate. | C31: Do not combine security-personnel or administrator forms with the student comparison. Keep those forms separate. | D31: Do not combine security-personnel or administrator forms with the student comparison. Keep those forms separate. | E31: Do not combine security-personnel or administrator forms with the student comparison. Keep those forms separate. | F31: Do not combine security-personnel or administrator forms with the student comparison. Keep those forms separate. | G31: Do not combine security-personnel or administrator forms with the student comparison. Keep those forms separate. | H31: Do not combine security-personnel or administrator forms with the student comparison. Keep those forms separate.
A33: This file does not test processing-time differences. Manual writing times and automated component timers do not measure the same complete task. | B33: This file does not test processing-time differences. Manual writing times and automated component timers do not measure the same complete task. | C33: This file does not test processing-time differences. Manual writing times and automated component timers do not measure the same complete task. | D33: This file does not test processing-time differences. Manual writing times and automated component timers do not measure the same complete task. | E33: This file does not test processing-time differences. Manual writing times and automated component timers do not measure the same complete task. | F33: This file does not test processing-time differences. Manual writing times and automated component timers do not measure the same complete task. | G33: This file does not test processing-time differences. Manual writing times and automated component timers do not measure the same complete task. | H33: This file does not test processing-time differences. Manual writing times and automated component timers do not measure the same complete task.
A35: Source for questionnaire order and wording: C:/Users/justine mendoza/Documents/METRICS first batch/UnStudent Weighted Mean - Students (1).pdf | B35: Source for questionnaire order and wording: C:/Users/justine mendoza/Documents/METRICS first batch/UnStudent Weighted Mean - Students (1).pdf | C35: Source for questionnaire order and wording: C:/Users/justine mendoza/Documents/METRICS first batch/UnStudent Weighted Mean - Students (1).pdf | D35: Source for questionnaire order and wording: C:/Users/justine mendoza/Documents/METRICS first batch/UnStudent Weighted Mean - Students (1).pdf | E35: Source for questionnaire order and wording: C:/Users/justine mendoza/Documents/METRICS first batch/UnStudent Weighted Mean - Students (1).pdf | F35: Source for questionnaire order and wording: C:/Users/justine mendoza/Documents/METRICS first batch/UnStudent Weighted Mean - Students (1).pdf | G35: Source for questionnaire order and wording: C:/Users/justine mendoza/Documents/METRICS first batch/UnStudent Weighted Mean - Students (1).pdf | H35: Source for questionnaire order and wording: C:/Users/justine mendoza/Documents/METRICS first batch/UnStudent Weighted Mean - Students (1).pdf

Sheet Manual
A1: Paper ID | B1: FS1 | C1: FS2 | D1: FS3 | E1: FS4 | F1: FS5 | G1: PE1 | H1: PE2 | I1: PE3 | J1: PE4 | K1: US1 | L1: US2 | M1: US3 | N1: US4 | O1: US5 | P1: RE1 | Q1: RE2 | R1: RE3 | S1: RE4 | T1: RE5 | U1: SE1 | V1: SE2 | W1: SE3 | X1: SE4 | Y1: SE5 | Z1: Functional Suitability | AA1: Performance Efficiency | AB1: Usability | AC1: Reliability | AD1: Security | AE1: Overall score | AF1: Entry status | AG1: Checked by
A2: M01 | B2: 3 | C2: 1 | D2: 2 | E2: 2 | F2: 4 | G2: 3 | H2: 3 | I2: 3 | J2: 3 | K2: 2 | L2: 3 | M2: 3 | N2: 2 | O2: 4 | P2: 4 | Q2: 3 | R2: 3 | S2: 4 | T2: 4 | U2: 4 | V2: 3 | W2: 3 | X2: 4 | Y2: 4 | Z2: =IF($AF2="Complete",AVERAGE(B2:F2),"") -> 2.4 | AA2: =IF($AF2="Complete",AVERAGE(G2:J2),"") -> 3 | AB2: =IF($AF2="Complete",AVERAGE(K2:O2),"") -> 2.8 | AC2: =IF($AF2="Complete",AVERAGE(P2:T2),"") -> 3.6 | AD2: =IF($AF2="Complete",AVERAGE(U2:Y2),"") -> 3.6 | AE2: =IF($AF2="Complete",AVERAGE(Z2:AD2),"") -> 3.08 | AF2: =IF(COUNTA(B2:Y2)=0,"Not entered",IF(AND(COUNT(B2:Y2)=24,COUNTIF(B2:Y2,1)+COUNTIF(B2:Y2,2)+COUNTIF(B2:Y2,3)+COUNTIF(B2:Y2,4)=24),"Complete","CHECK PAPER")) -> Complete
A3: M02 | B3: 3 | C3: 3 | D3: 2 | E3: 2 | F3: 3 | G3: 3 | H3: 1 | I3: 1 | J3: 2 | K3: 4 | L3: 3 | M3: 3 | N3: 3 | O3: 2 | P3: 3 | Q3: 3 | R3: 3 | S3: 3 | T3: 2 | U3: 3 | V3: 3 | W3: 3 | X3: 3 | Y3: 3 | Z3: =IF($AF3="Complete",AVERAGE(B3:F3),"") -> 2.6 | AA3: =IF($AF3="Complete",AVERAGE(G3:J3),"") -> 1.75 | AB3: =IF($AF3="Complete",AVERAGE(K3:O3),"") -> 3 | AC3: =IF($AF3="Complete",AVERAGE(P3:T3),"") -> 2.8 | AD3: =IF($AF3="Complete",AVERAGE(U3:Y3),"") -> 3 | AE3: =IF($AF3="Complete",AVERAGE(Z3:AD3),"") -> 2.63 | AF3: =IF(COUNTA(B3:Y3)=0,"Not entered",IF(AND(COUNT(B3:Y3)=24,COUNTIF(B3:Y3,1)+COUNTIF(B3:Y3,2)+COUNTIF(B3:Y3,3)+COUNTIF(B3:Y3,4)=24),"Complete","CHECK PAPER")) -> Complete
A4: M03 | B4: 2 | C4: 2 | D4: 3 | E4: 2 | F4: 3 | G4: 3 | H4: 2 | I4: 1 | J4: 1 | K4: 2 | L4: 3 | M4: 2 | N4: 3 | O4: 3 | P4: 2 | Q4: 2 | R4: 1 | S4: 2 | T4: 1 | U4: 2 | V4: 3 | W4: 2 | X4: 1 | Y4: 3 | Z4: =IF($AF4="Complete",AVERAGE(B4:F4),"") -> 2.4 | AA4: =IF($AF4="Complete",AVERAGE(G4:J4),"") -> 1.75 | AB4: =IF($AF4="Complete",AVERAGE(K4:O4),"") -> 2.6 | AC4: =IF($AF4="Complete",AVERAGE(P4:T4),"") -> 1.6 | AD4: =IF($AF4="Complete",AVERAGE(U4:Y4),"") -> 2.2 | AE4: =IF($AF4="Complete",AVERAGE(Z4:AD4),"") -> 2.11 | AF4: =IF(COUNTA(B4:Y4)=0,"Not entered",IF(AND(COUNT(B4:Y4)=24,COUNTIF(B4:Y4,1)+COUNTIF(B4:Y4,2)+COUNTIF(B4:Y4,3)+COUNTIF(B4:Y4,4)=24),"Complete","CHECK PAPER")) -> Complete
A5: M04 | B5: 3 | C5: 3 | D5: 2 | E5: 3 | F5: 3 | G5: 2 | H5: 2 | I5: 2 | J5: 2 | K5: 3 | L5: 3 | M5: 3 | N5: 3 | O5: 3 | P5: 4 | Q5: 4 | R5: 4 | S5: 4 | T5: 4 | U5: 3 | V5: 3 | W5: 4 | X5: 4 | Y5: 3 | Z5: =IF($AF5="Complete",AVERAGE(B5:F5),"") -> 2.8 | AA5: =IF($AF5="Complete",AVERAGE(G5:J5),"") -> 2 | AB5: =IF($AF5="Complete",AVERAGE(K5:O5),"") -> 3 | AC5: =IF($AF5="Complete",AVERAGE(P5:T5),"") -> 4 | AD5: =IF($AF5="Complete",AVERAGE(U5:Y5),"") -> 3.4 | AE5: =IF($AF5="Complete",AVERAGE(Z5:AD5),"") -> 3.04 | AF5: =IF(COUNTA(B5:Y5)=0,"Not entered",IF(AND(COUNT(B5:Y5)=24,COUNTIF(B5:Y5,1)+COUNTIF(B5:Y5,2)+COUNTIF(B5:Y5,3)+COUNTIF(B5:Y5,4)=24),"Complete","CHECK PAPER")) -> Complete
A6: M05 | B6: 1 | C6: 1 | D6: 1 | E6: 1 | F6: 2 | G6: 2 | H6: 2 | I6: 1 | J6: 2 | K6: 2 | L6: 1 | M6: 1 | N6: 1 | O6: 2 | P6: 2 | Q6: 2 | R6: 2 | S6: 1 | T6: 1 | U6: 1 | V6: 1 | W6: 2 | X6: 1 | Y6: 2 | Z6: =IF($AF6="Complete",AVERAGE(B6:F6),"") -> 1.2 | AA6: =IF($AF6="Complete",AVERAGE(G6:J6),"") -> 1.75 | AB6: =IF($AF6="Complete",AVERAGE(K6:O6),"") -> 1.4 | AC6: =IF($AF6="Complete",AVERAGE(P6:T6),"") -> 1.6 | AD6: =IF($AF6="Complete",AVERAGE(U6:Y6),"") -> 1.4 | AE6: =IF($AF6="Complete",AVERAGE(Z6:AD6),"") -> 1.47 | AF6: =IF(COUNTA(B6:Y6)=0,"Not entered",IF(AND(COUNT(B6:Y6)=24,COUNTIF(B6:Y6,1)+COUNTIF(B6:Y6,2)+COUNTIF(B6:Y6,3)+COUNTIF(B6:Y6,4)=24),"Complete","CHECK PAPER")) -> Complete
A7: M06 | B7: 3 | C7: 4 | D7: 3 | E7: 4 | F7: 3 | G7: 2 | H7: 2 | I7: 3 | J7: 3 | K7: 3 | L7: 3 | M7: 3 | N7: 4 | O7: 3 | P7: 3 | Q7: 2 | R7: 3 | S7: 3 | T7: 3 | U7: 4 | V7: 3 | W7: 3 | X7: 3 | Y7: 2 | Z7: =IF($AF7="Complete",AVERAGE(B7:F7),"") -> 3.4 | AA7: =IF($AF7="Complete",AVERAGE(G7:J7),"") -> 2.5 | AB7: =IF($AF7="Complete",AVERAGE(K7:O7),"") -> 3.2 | AC7: =IF($AF7="Complete",AVERAGE(P7:T7),"") -> 2.8 | AD7: =IF($AF7="Complete",AVERAGE(U7:Y7),"") -> 3 | AE7: =IF($AF7="Complete",AVERAGE(Z7:AD7),"") -> 2.98 | AF7: =IF(COUNTA(B7:Y7)=0,"Not entered",IF(AND(COUNT(B7:Y7)=24,COUNTIF(B7:Y7,1)+COUNTIF(B7:Y7,2)+COUNTIF(B7:Y7,3)+COUNTIF(B7:Y7,4)=24),"Complete","CHECK PAPER")) -> Complete
A8: M07 | B8: 3 | C8: 3 | D8: 2 | E8: 2 | F8: 2 | G8: 2 | H8: 1 | I8: 1 | J8: 1 | K8: 3 | L8: 3 | M8: 2 | N8: 3 | O8: 3 | P8: 3 | Q8: 2 | R8: 1 | S8: 1 | T8: 1 | U8: 2 | V8: 1 | W8: 2 | X8: 2 | Y8: 2 | Z8: =IF($AF8="Complete",AVERAGE(B8:F8),"") -> 2.4 | AA8: =IF($AF8="Complete",AVERAGE(G8:J8),"") -> 1.25 | AB8: =IF($AF8="Complete",AVERAGE(K8:O8),"") -> 2.8 | AC8: =IF($AF8="Complete",AVERAGE(P8:T8),"") -> 1.6 | AD8: =IF($AF8="Complete",AVERAGE(U8:Y8),"") -> 1.8 | AE8: =IF($AF8="Complete",AVERAGE(Z8:AD8),"") -> 1.97 | AF8: =IF(COUNTA(B8:Y8)=0,"Not entered",IF(AND(COUNT(B8:Y8)=24,COUNTIF(B8:Y8,1)+COUNTIF(B8:Y8,2)+COUNTIF(B8:Y8,3)+COUNTIF(B8:Y8,4)=24),"Complete","CHECK PAPER")) -> Complete
A9: M08 | B9: 3 | C9: 3 | D9: 2 | E9: 2 | F9: 2 | G9: 1 | H9: 2 | I9: 1 | J9: 2 | K9: 3 | L9: 3 | M9: 3 | N9: 4 | O9: 4 | P9: 4 | Q9: 3 | R9: 2 | S9: 2 | T9: 2 | U9: 2 | V9: 2 | W9: 2 | X9: 2 | Y9: 2 | Z9: =IF($AF9="Complete",AVERAGE(B9:F9),"") -> 2.4 | AA9: =IF($AF9="Complete",AVERAGE(G9:J9),"") -> 1.5 | AB9: =IF($AF9="Complete",AVERAGE(K9:O9),"") -> 3.4 | AC9: =IF($AF9="Complete",AVERAGE(P9:T9),"") -> 2.6 | AD9: =IF($AF9="Complete",AVERAGE(U9:Y9),"") -> 2 | AE9: =IF($AF9="Complete",AVERAGE(Z9:AD9),"") -> 2.38 | AF9: =IF(COUNTA(B9:Y9)=0,"Not entered",IF(AND(COUNT(B9:Y9)=24,COUNTIF(B9:Y9,1)+COUNTIF(B9:Y9,2)+COUNTIF(B9:Y9,3)+COUNTIF(B9:Y9,4)=24),"Complete","CHECK PAPER")) -> Complete
A10: M09 | B10: 3 | C10: 3 | D10: 3 | E10: 3 | F10: 3 | G10: 2 | H10: 2 | I10: 2 | J10: 2 | K10: 2 | L10: 2 | M10: 2 | N10: 3 | O10: 2 | P10: 2 | Q10: 2 | R10: 2 | S10: 2 | T10: 2 | U10: 2 | V10: 2 | W10: 2 | X10: 2 | Y10: 2 | Z10: =IF($AF10="Complete",AVERAGE(B10:F10),"") -> 3 | AA10: =IF($AF10="Complete",AVERAGE(G10:J10),"") -> 2 | AB10: =IF($AF10="Complete",AVERAGE(K10:O10),"") -> 2.2 | AC10: =IF($AF10="Complete",AVERAGE(P10:T10),"") -> 2 | AD10: =IF($AF10="Complete",AVERAGE(U10:Y10),"") -> 2 | AE10: =IF($AF10="Complete",AVERAGE(Z10:AD10),"") -> 2.24 | AF10: =IF(COUNTA(B10:Y10)=0,"Not entered",IF(AND(COUNT(B10:Y10)=24,COUNTIF(B10:Y10,1)+COUNTIF(B10:Y10,2)+COUNTIF(B10:Y10,3)+COUNTIF(B10:Y10,4)=24),"Complete","CHECK PAPER")) -> Complete
A11: M10 | B11: 2 | C11: 2 | D11: 4 | E11: 2 | F11: 4 | G11: 3 | H11: 2 | I11: 1 | J11: 2 | K11: 4 | L11: 3 | M11: 2 | N11: 3 | O11: 3 | P11: 2 | Q11: 2 | R11: 2 | S11: 1 | T11: 2 | U11: 2 | V11: 2 | W11: 2 | X11: 2 | Y11: 2 | Z11: =IF($AF11="Complete",AVERAGE(B11:F11),"") -> 2.8 | AA11: =IF($AF11="Complete",AVERAGE(G11:J11),"") -> 2 | AB11: =IF($AF11="Complete",AVERAGE(K11:O11),"") -> 3 | AC11: =IF($AF11="Complete",AVERAGE(P11:T11),"") -> 1.8 | AD11: =IF($AF11="Complete",AVERAGE(U11:Y11),"") -> 2 | AE11: =IF($AF11="Complete",AVERAGE(Z11:AD11),"") -> 2.32 | AF11: =IF(COUNTA(B11:Y11)=0,"Not entered",IF(AND(COUNT(B11:Y11)=24,COUNTIF(B11:Y11,1)+COUNTIF(B11:Y11,2)+COUNTIF(B11:Y11,3)+COUNTIF(B11:Y11,4)=24),"Complete","CHECK PAPER")) -> Complete
A12: M11 | B12: 3 | C12: 4 | D12: 3 | E12: 3 | F12: 4 | G12: 2 | H12: 2 | I12: 2 | J12: 2 | K12: 3 | L12: 4 | M12: 3 | N12: 4 | O12: 3 | P12: 2 | Q12: 3 | R12: 3 | S12: 2 | T12: 3 | U12: 2 | V12: 3 | W12: 2 | X12: 3 | Y12: 2 | Z12: =IF($AF12="Complete",AVERAGE(B12:F12),"") -> 3.4 | AA12: =IF($AF12="Complete",AVERAGE(G12:J12),"") -> 2 | AB12: =IF($AF12="Complete",AVERAGE(K12:O12),"") -> 3.4 | AC12: =IF($AF12="Complete",AVERAGE(P12:T12),"") -> 2.6 | AD12: =IF($AF12="Complete",AVERAGE(U12:Y12),"") -> 2.4 | AE12: =IF($AF12="Complete",AVERAGE(Z12:AD12),"") -> 2.76 | AF12: =IF(COUNTA(B12:Y12)=0,"Not entered",IF(AND(COUNT(B12:Y12)=24,COUNTIF(B12:Y12,1)+COUNTIF(B12:Y12,2)+COUNTIF(B12:Y12,3)+COUNTIF(B12:Y12,4)=24),"Complete","CHECK PAPER")) -> Complete
A13: M12 | B13: 4 | C13: 2 | D13: 2 | E13: 2 | F13: 2 | G13: 1 | H13: 1 | I13: 2 | J13: 1 | K13: 3 | L13: 3 | M13: 2 | N13: 4 | O13: 4 | P13: 3 | Q13: 2 | R13: 3 | S13: 2 | T13: 2 | U13: 3 | V13: 4 | W13: 3 | X13: 3 | Y13: 2 | Z13: =IF($AF13="Complete",AVERAGE(B13:F13),"") -> 2.4 | AA13: =IF($AF13="Complete",AVERAGE(G13:J13),"") -> 1.25 | AB13: =IF($AF13="Complete",AVERAGE(K13:O13),"") -> 3.2 | AC13: =IF($AF13="Complete",AVERAGE(P13:T13),"") -> 2.4 | AD13: =IF($AF13="Complete",AVERAGE(U13:Y13),"") -> 3 | AE13: =IF($AF13="Complete",AVERAGE(Z13:AD13),"") -> 2.45 | AF13: =IF(COUNTA(B13:Y13)=0,"Not entered",IF(AND(COUNT(B13:Y13)=24,COUNTIF(B13:Y13,1)+COUNTIF(B13:Y13,2)+COUNTIF(B13:Y13,3)+COUNTIF(B13:Y13,4)=24),"Complete","CHECK PAPER")) -> Complete
... A71: M70 | B71: 2 | C71: 3 | D71: 4 | E71: 4 | F71: 4 | G71: 1 | H71: 1 | I71: 1 | J71: 1 | K71: 4 | L71: 4 | M71: 4 | N71: 4 | O71: 4 | P71: 2 | Q71: 1 | R71: 2 | S71: 2 | T71: 2 | U71: 1 | V71: 2 | W71: 2 | X71: 2 | Y71: 1 | Z71: =IF($AF71="Complete",AVERAGE(B71:F71),"") -> 3.4 | AA71: =IF($AF71="Complete",AVERAGE(G71:J71),"") -> 1 | AB71: =IF($AF71="Complete",AVERAGE(K71:O71),"") -> 4 | AC71: =IF($AF71="Complete",AVERAGE(P71:T71),"") -> 1.8 | AD71: =IF($AF71="Complete",AVERAGE(U71:Y71),"") -> 1.6 | AE71: =IF($AF71="Complete",AVERAGE(Z71:AD71),"") -> 2.36 | AF71: =IF(COUNTA(B71:Y71)=0,"Not entered",IF(AND(COUNT(B71:Y71)=24,COUNTIF(B71:Y71,1)+COUNTIF(B71:Y71,2)+COUNTIF(B71:Y71,3)+COUNTIF(B71:Y71,4)=24),"Complete","CHECK PAPER")) -> Complete
A74: Manual: enter one paper per row. Yellow answer cells accept whole numbers 1-4 only. Do not enter names or student IDs. | B74: Manual: enter one paper per row. Yellow answer cells accept whole numbers 1-4 only. Do not enter names or student IDs. | C74: Manual: enter one paper per row. Yellow answer cells accept whole numbers 1-4 only. Do not enter names or student IDs. | D74: Manual: enter one paper per row. Yellow answer cells accept whole numbers 1-4 only. Do not enter names or student IDs. | E74: Manual: enter one paper per row. Yellow answer cells accept whole numbers 1-4 only. Do not enter names or student IDs. | F74: Manual: enter one paper per row. Yellow answer cells accept whole numbers 1-4 only. Do not enter names or student IDs. | G74: Manual: enter one paper per row. Yellow answer cells accept whole numbers 1-4 only. Do not enter names or student IDs. | H74: Manual: enter one paper per row. Yellow answer cells accept whole numbers 1-4 only. Do not enter names or student IDs. | I74: Manual: enter one paper per row. Yellow answer cells accept whole numbers 1-4 only. Do not enter names or student IDs. | J74: Manual: enter one paper per row. Yellow answer cells accept whole numbers 1-4 only. Do not enter names or student IDs. | K74: Manual: enter one paper per row. Yellow answer cells accept whole numbers 1-4 only. Do not enter names or student IDs.
A75: Use the question key below to match section and item numbers. Leave missing or unclear answers blank; do not guess. | B75: Use the question key below to match section and item numbers. Leave missing or unclear answers blank; do not guess. | C75: Use the question key below to match section and item numbers. Leave missing or unclear answers blank; do not guess. | D75: Use the question key below to match section and item numbers. Leave missing or unclear answers blank; do not guess. | E75: Use the question key below to match section and item numbers. Leave missing or unclear answers blank; do not guess. | F75: Use the question key below to match section and item numbers. Leave missing or unclear answers blank; do not guess. | G75: Use the question key below to match section and item numbers. Leave missing or unclear answers blank; do not guess. | H75: Use the question key below to match section and item numbers. Leave missing or unclear answers blank; do not guess. | I75: Use the question key below to match section and item numbers. Leave missing or unclear answers blank; do not guess. | J75: Use the question key below to match section and item numbers. Leave missing or unclear answers blank; do not guess. | K75: Use the question key below to match section and item numbers. Leave missing or unclear answers blank; do not guess.
A77: Item code | B77: Question wording in the supplied tally | C77: Question wording in the supplied tally | D77: Question wording in the supplied tally | E77: Question wording in the supplied tally | F77: Question wording in the supplied tally | G77: Question wording in the supplied tally | H77: Question wording in the supplied tally | I77: Question wording in the supplied tally | J77: Question wording in the supplied tally | K77: Question wording in the supplied tally
A78: FS1 | B78: The manual process provides a clear way to verify my identity when attending a university event. | C78: The manual process provides a clear way to verify my identity when attending a university event. | D78: The manual process provides a clear way to verify my identity when attending a university event. | E78: The manual process provides a clear way to verify my identity when attending a university event. | F78: The manual process provides a clear way to verify my identity when attending a university event. | G78: The manual process provides a clear way to verify my identity when attending a university event. | H78: The manual process provides a clear way to verify my identity when attending a university event. | I78: The manual process provides a clear way to verify my identity when attending a university event. | J78: The manual process provides a clear way to verify my identity when attending a university event. | K78: The manual process provides a clear way to verify my identity when attending a university event.
A79: FS2 | B79: The manual process accurately and completely records my entry information. | C79: The manual process accurately and completely records my entry information. | D79: The manual process accurately and completely records my entry information. | E79: The manual process accurately and completely records my entry information. | F79: The manual process accurately and completely records my entry information. | G79: The manual process accurately and completely records my entry information. | H79: The manual process accurately and completely records my entry information. | I79: The manual process accurately and completely records my entry information. | J79: The manual process accurately and completely records my entry information. | K79: The manual process accurately and completely records my entry information.
A80: FS3 | B80: The paper-based attendance procedures are relevant to monitoring student attendance. | C80: The paper-based attendance procedures are relevant to monitoring student attendance. | D80: The paper-based attendance procedures are relevant to monitoring student attendance. | E80: The paper-based attendance procedures are relevant to monitoring student attendance. | F80: The paper-based attendance procedures are relevant to monitoring student attendance. | G80: The paper-based attendance procedures are relevant to monitoring student attendance. | H80: The paper-based attendance procedures are relevant to monitoring student attendance. | I80: The paper-based attendance procedures are relevant to monitoring student attendance. | J80: The paper-based attendance procedures are relevant to monitoring student attendance. | K80: The paper-based attendance procedures are relevant to monitoring student attendance.
A81: FS4 | B81: The manual process provides clear confirmation that my attendance has been recorded (e.g., staff confirmation or completed sign-in). | C81: The manual process provides clear confirmation that my attendance has been recorded (e.g., staff confirmation or completed sign-in). | D81: The manual process provides clear confirmation that my attendance has been recorded (e.g., staff confirmation or completed sign-in). | E81: The manual process provides clear confirmation that my attendance has been recorded (e.g., staff confirmation or completed sign-in). | F81: The manual process provides clear confirmation that my attendance has been recorded (e.g., staff confirmation or completed sign-in). | G81: The manual process provides clear confirmation that my attendance has been recorded (e.g., staff confirmation or completed sign-in). | H81: The manual process provides clear confirmation that my attendance has been recorded (e.g., staff confirmation or completed sign-in). | I81: The manual process provides clear confirmation that my attendance has been recorded (e.g., staff confirmation or completed sign-in). | J81: The manual process provides clear confirmation that my attendance has been recorded (e.g., staff confirmation or completed sign-in). | K81: The manual process provides clear confirmation that my attendance has been recorded (e.g., staff confirmation or completed sign-in).
A82: FS5 | B82: Overall, the manual process meets the basic requirements for recording event attendance. | C82: Overall, the manual process meets the basic requirements for recording event attendance. | D82: Overall, the manual process meets the basic requirements for recording event attendance. | E82: Overall, the manual process meets the basic requirements for recording event attendance. | F82: Overall, the manual process meets the basic requirements for recording event attendance. | G82: Overall, the manual process meets the basic requirements for recording event attendance. | H82: Overall, the manual process meets the basic requirements for recording event attendance. | I82: Overall, the manual process meets the basic requirements for recording event attendance. | J82: Overall, the manual process meets the basic requirements for recording event attendance. | K82: Overall, the manual process meets the basic requirements for recording event attendance.
A83: PE1 | B83: The manual process is completed quickly when I sign the attendance sheet. | C83: The manual process is completed quickly when I sign the attendance sheet. | D83: The manual process is completed quickly when I sign the attendance sheet. | E83: The manual process is completed quickly when I sign the attendance sheet. | F83: The manual process is completed quickly when I sign the attendance sheet. | G83: The manual process is completed quickly when I sign the attendance sheet. | H83: The manual process is completed quickly when I sign the attendance sheet. | I83: The manual process is completed quickly when I sign the attendance sheet. | J83: The manual process is completed quickly when I sign the attendance sheet. | K83: The manual process is completed quickly when I sign the attendance sheet.
A84: PE2 | B84: The manual process remains manageable even when there is a long line of students. | C84: The manual process remains manageable even when there is a long line of students. | D84: The manual process remains manageable even when there is a long line of students. | E84: The manual process remains manageable even when there is a long line of students. | F84: The manual process remains manageable even when there is a long line of students. | G84: The manual process remains manageable even when there is a long line of students. | H84: The manual process remains manageable even when there is a long line of students. | I84: The manual process remains manageable even when there is a long line of students. | J84: The manual process remains manageable even when there is a long line of students. | K84: The manual process remains manageable even when there is a long line of students.
A85: PE3 | B85: The manual process maintains a consistent processing speed throughout the attendance procedure. | C85: The manual process maintains a consistent processing speed throughout the attendance procedure. | D85: The manual process maintains a consistent processing speed throughout the attendance procedure. | E85: The manual process maintains a consistent processing speed throughout the attendance procedure. | F85: The manual process maintains a consistent processing speed throughout the attendance procedure. | G85: The manual process maintains a consistent processing speed throughout the attendance procedure. | H85: The manual process maintains a consistent processing speed throughout the attendance procedure. | I85: The manual process maintains a consistent processing speed throughout the attendance procedure. | J85: The manual process maintains a consistent processing speed throughout the attendance procedure. | K85: The manual process maintains a consistent processing speed throughout the attendance procedure.
A86: PE4 | B86: The overall speed of the manual process meets my expectations for event attendance. | C86: The overall speed of the manual process meets my expectations for event attendance. | D86: The overall speed of the manual process meets my expectations for event attendance. | E86: The overall speed of the manual process meets my expectations for event attendance. | F86: The overall speed of the manual process meets my expectations for event attendance. | G86: The overall speed of the manual process meets my expectations for event attendance. | H86: The overall speed of the manual process meets my expectations for event attendance. | I86: The overall speed of the manual process meets my expectations for event attendance. | J86: The overall speed of the manual process meets my expectations for event attendance. | K86: The overall speed of the manual process meets my expectations for event attendance.
... A103: Question key source: C:/Users/justine mendoza/Documents/METRICS first batch/UnStudent Weighted Mean - Students (1).pdf | B103: Question key source: C:/Users/justine mendoza/Documents/METRICS first batch/UnStudent Weighted Mean - Students (1).pdf | C103: Question key source: C:/Users/justine mendoza/Documents/METRICS first batch/UnStudent Weighted Mean - Students (1).pdf | D103: Question key source: C:/Users/justine mendoza/Documents/METRICS first batch/UnStudent Weighted Mean - Students (1).pdf | E103: Question key source: C:/Users/justine mendoza/Documents/METRICS first batch/UnStudent Weighted Mean - Students (1).pdf | F103: Question key source: C:/Users/justine mendoza/Documents/METRICS first batch/UnStudent Weighted Mean - Students (1).pdf | G103: Question key source: C:/Users/justine mendoza/Documents/METRICS first batch/UnStudent Weighted Mean - Students (1).pdf | H103: Question key source: C:/Users/justine mendoza/Documents/METRICS first batch/UnStudent Weighted Mean - Students (1).pdf | I103: Question key source: C:/Users/justine mendoza/Documents/METRICS first batch/UnStudent Weighted Mean - Students (1).pdf | J103: Question key source: C:/Users/justine mendoza/Documents/METRICS first batch/UnStudent Weighted Mean - Students (1).pdf | K103: Question key source: C:/Users/justine mendoza/Documents/METRICS first batch/UnStudent Weighted Mean - Students (1).pdf

Sheet System
A1: Paper ID | B1: FS1 | C1: FS2 | D1: FS3 | E1: FS4 | F1: FS5 | G1: PE1 | H1: PE2 | I1: PE3 | J1: PE4 | K1: US1 | L1: US2 | M1: US3 | N1: US4 | O1: US5 | P1: RE1 | Q1: RE2 | R1: RE3 | S1: RE4 | T1: RE5 | U1: SE1 | V1: SE2 | W1: SE3 | X1: SE4 | Y1: SE5 | Z1: Functional Suitability | AA1: Performance Efficiency | AB1: Usability | AC1: Reliability | AD1: Security | AE1: Overall score | AF1: Entry status | AG1: Checked by
A2: S01 | B2: 4 | C2: 4 | D2: 4 | E2: 4 | F2: 4 | G2: 4 | H2: 4 | I2: 4 | J2: 4 | K2: 4 | L2: 4 | M2: 4 | N2: 4 | O2: 4 | P2: 4 | Q2: 4 | R2: 4 | S2: 4 | T2: 4 | U2: 4 | V2: 4 | W2: 4 | X2: 4 | Y2: 4 | Z2: =IF($AF2="Complete",AVERAGE(B2:F2),"") -> 4 | AA2: =IF($AF2="Complete",AVERAGE(G2:J2),"") -> 4 | AB2: =IF($AF2="Complete",AVERAGE(K2:O2),"") -> 4 | AC2: =IF($AF2="Complete",AVERAGE(P2:T2),"") -> 4 | AD2: =IF($AF2="Complete",AVERAGE(U2:Y2),"") -> 4 | AE2: =IF($AF2="Complete",AVERAGE(Z2:AD2),"") -> 4 | AF2: =IF(COUNTA(B2:Y2)=0,"Not entered",IF(AND(COUNT(B2:Y2)=24,COUNTIF(B2:Y2,1)+COUNTIF(B2:Y2,2)+COUNTIF(B2:Y2,3)+COUNTIF(B2:Y2,4)=24),"Complete","CHECK PAPER")) -> Complete
A3: S02 | B3: 4 | C3: 4 | D3: 4 | E3: 4 | F3: 4 | G3: 4 | H3: 4 | I3: 4 | J3: 4 | K3: 4 | L3: 4 | M3: 4 | N3: 4 | O3: 4 | P3: 4 | Q3: 4 | R3: 4 | S3: 4 | T3: 4 | U3: 4 | V3: 4 | W3: 4 | X3: 4 | Y3: 4 | Z3: =IF($AF3="Complete",AVERAGE(B3:F3),"") -> 4 | AA3: =IF($AF3="Complete",AVERAGE(G3:J3),"") -> 4 | AB3: =IF($AF3="Complete",AVERAGE(K3:O3),"") -> 4 | AC3: =IF($AF3="Complete",AVERAGE(P3:T3),"") -> 4 | AD3: =IF($AF3="Complete",AVERAGE(U3:Y3),"") -> 4 | AE3: =IF($AF3="Complete",AVERAGE(Z3:AD3),"") -> 4 | AF3: =IF(COUNTA(B3:Y3)=0,"Not entered",IF(AND(COUNT(B3:Y3)=24,COUNTIF(B3:Y3,1)+COUNTIF(B3:Y3,2)+COUNTIF(B3:Y3,3)+COUNTIF(B3:Y3,4)=24),"Complete","CHECK PAPER")) -> Complete
A4: S03 | B4: 4 | C4: 4 | D4: 4 | E4: 4 | F4: 4 | G4: 4 | H4: 4 | I4: 4 | J4: 4 | K4: 4 | L4: 4 | M4: 4 | N4: 4 | O4: 4 | P4: 4 | Q4: 4 | R4: 4 | S4: 4 | T4: 4 | U4: 4 | V4: 4 | W4: 4 | X4: 4 | Y4: 4 | Z4: =IF($AF4="Complete",AVERAGE(B4:F4),"") -> 4 | AA4: =IF($AF4="Complete",AVERAGE(G4:J4),"") -> 4 | AB4: =IF($AF4="Complete",AVERAGE(K4:O4),"") -> 4 | AC4: =IF($AF4="Complete",AVERAGE(P4:T4),"") -> 4 | AD4: =IF($AF4="Complete",AVERAGE(U4:Y4),"") -> 4 | AE4: =IF($AF4="Complete",AVERAGE(Z4:AD4),"") -> 4 | AF4: =IF(COUNTA(B4:Y4)=0,"Not entered",IF(AND(COUNT(B4:Y4)=24,COUNTIF(B4:Y4,1)+COUNTIF(B4:Y4,2)+COUNTIF(B4:Y4,3)+COUNTIF(B4:Y4,4)=24),"Complete","CHECK PAPER")) -> Complete
A5: S04 | B5: 4 | C5: 4 | D5: 4 | E5: 4 | F5: 4 | G5: 4 | H5: 4 | I5: 4 | J5: 4 | K5: 4 | L5: 3 | M5: 4 | N5: 4 | O5: 4 | P5: 3 | Q5: 3 | R5: 3 | S5: 3 | T5: 3 | U5: 4 | V5: 4 | W5: 4 | X5: 4 | Y5: 4 | Z5: =IF($AF5="Complete",AVERAGE(B5:F5),"") -> 4 | AA5: =IF($AF5="Complete",AVERAGE(G5:J5),"") -> 4 | AB5: =IF($AF5="Complete",AVERAGE(K5:O5),"") -> 3.8 | AC5: =IF($AF5="Complete",AVERAGE(P5:T5),"") -> 3 | AD5: =IF($AF5="Complete",AVERAGE(U5:Y5),"") -> 4 | AE5: =IF($AF5="Complete",AVERAGE(Z5:AD5),"") -> 3.76 | AF5: =IF(COUNTA(B5:Y5)=0,"Not entered",IF(AND(COUNT(B5:Y5)=24,COUNTIF(B5:Y5,1)+COUNTIF(B5:Y5,2)+COUNTIF(B5:Y5,3)+COUNTIF(B5:Y5,4)=24),"Complete","CHECK PAPER")) -> Complete
A6: S05 | B6: 4 | C6: 4 | D6: 4 | E6: 4 | F6: 4 | G6: 3 | H6: 4 | I6: 4 | J6: 4 | K6: 4 | L6: 4 | M6: 4 | N6: 4 | O6: 4 | P6: 3 | Q6: 3 | R6: 4 | S6: 4 | T6: 3 | U6: 3 | V6: 4 | W6: 4 | X6: 4 | Y6: 4 | Z6: =IF($AF6="Complete",AVERAGE(B6:F6),"") -> 4 | AA6: =IF($AF6="Complete",AVERAGE(G6:J6),"") -> 3.75 | AB6: =IF($AF6="Complete",AVERAGE(K6:O6),"") -> 4 | AC6: =IF($AF6="Complete",AVERAGE(P6:T6),"") -> 3.4 | AD6: =IF($AF6="Complete",AVERAGE(U6:Y6),"") -> 3.8 | AE6: =IF($AF6="Complete",AVERAGE(Z6:AD6),"") -> 3.79 | AF6: =IF(COUNTA(B6:Y6)=0,"Not entered",IF(AND(COUNT(B6:Y6)=24,COUNTIF(B6:Y6,1)+COUNTIF(B6:Y6,2)+COUNTIF(B6:Y6,3)+COUNTIF(B6:Y6,4)=24),"Complete","CHECK PAPER")) -> Complete
A7: S06 | B7: 4 | C7: 4 | D7: 4 | E7: 4 | F7: 4 | G7: 4 | H7: 3 | I7: 3 | J7: 3 | K7: 3 | L7: 4 | M7: 4 | N7: 4 | O7: 4 | P7: 3 | Q7: 4 | R7: 4 | S7: 4 | T7: 4 | U7: 4 | V7: 4 | W7: 4 | X7: 4 | Y7: 4 | Z7: =IF($AF7="Complete",AVERAGE(B7:F7),"") -> 4 | AA7: =IF($AF7="Complete",AVERAGE(G7:J7),"") -> 3.25 | AB7: =IF($AF7="Complete",AVERAGE(K7:O7),"") -> 3.8 | AC7: =IF($AF7="Complete",AVERAGE(P7:T7),"") -> 3.8 | AD7: =IF($AF7="Complete",AVERAGE(U7:Y7),"") -> 4 | AE7: =IF($AF7="Complete",AVERAGE(Z7:AD7),"") -> 3.77 | AF7: =IF(COUNTA(B7:Y7)=0,"Not entered",IF(AND(COUNT(B7:Y7)=24,COUNTIF(B7:Y7,1)+COUNTIF(B7:Y7,2)+COUNTIF(B7:Y7,3)+COUNTIF(B7:Y7,4)=24),"Complete","CHECK PAPER")) -> Complete
A8: S07 | B8: 4 | C8: 4 | D8: 4 | E8: 4 | F8: 4 | G8: 4 | H8: 4 | I8: 4 | J8: 4 | K8: 4 | L8: 4 | M8: 4 | N8: 4 | O8: 4 | P8: 4 | Q8: 4 | R8: 4 | S8: 4 | T8: 4 | U8: 4 | V8: 4 | W8: 4 | X8: 4 | Y8: 4 | Z8: =IF($AF8="Complete",AVERAGE(B8:F8),"") -> 4 | AA8: =IF($AF8="Complete",AVERAGE(G8:J8),"") -> 4 | AB8: =IF($AF8="Complete",AVERAGE(K8:O8),"") -> 4 | AC8: =IF($AF8="Complete",AVERAGE(P8:T8),"") -> 4 | AD8: =IF($AF8="Complete",AVERAGE(U8:Y8),"") -> 4 | AE8: =IF($AF8="Complete",AVERAGE(Z8:AD8),"") -> 4 | AF8: =IF(COUNTA(B8:Y8)=0,"Not entered",IF(AND(COUNT(B8:Y8)=24,COUNTIF(B8:Y8,1)+COUNTIF(B8:Y8,2)+COUNTIF(B8:Y8,3)+COUNTIF(B8:Y8,4)=24),"Complete","CHECK PAPER")) -> Complete
A9: S08 | B9: 4 | C9: 4 | D9: 4 | E9: 4 | F9: 4 | G9: 4 | H9: 4 | I9: 4 | J9: 4 | K9: 4 | L9: 4 | M9: 4 | N9: 4 | O9: 4 | P9: 4 | Q9: 4 | R9: 4 | S9: 4 | T9: 4 | U9: 4 | V9: 4 | W9: 4 | X9: 4 | Y9: 4 | Z9: =IF($AF9="Complete",AVERAGE(B9:F9),"") -> 4 | AA9: =IF($AF9="Complete",AVERAGE(G9:J9),"") -> 4 | AB9: =IF($AF9="Complete",AVERAGE(K9:O9),"") -> 4 | AC9: =IF($AF9="Complete",AVERAGE(P9:T9),"") -> 4 | AD9: =IF($AF9="Complete",AVERAGE(U9:Y9),"") -> 4 | AE9: =IF($AF9="Complete",AVERAGE(Z9:AD9),"") -> 4 | AF9: =IF(COUNTA(B9:Y9)=0,"Not entered",IF(AND(COUNT(B9:Y9)=24,COUNTIF(B9:Y9,1)+COUNTIF(B9:Y9,2)+COUNTIF(B9:Y9,3)+COUNTIF(B9:Y9,4)=24),"Complete","CHECK PAPER")) -> Complete
A10: S09 | B10: 4 | C10: 4 | D10: 4 | E10: 4 | F10: 4 | G10: 4 | H10: 4 | I10: 4 | J10: 4 | K10: 4 | L10: 4 | M10: 4 | N10: 4 | O10: 4 | P10: 4 | Q10: 4 | R10: 4 | S10: 4 | T10: 4 | U10: 4 | V10: 4 | W10: 4 | X10: 4 | Y10: 4 | Z10: =IF($AF10="Complete",AVERAGE(B10:F10),"") -> 4 | AA10: =IF($AF10="Complete",AVERAGE(G10:J10),"") -> 4 | AB10: =IF($AF10="Complete",AVERAGE(K10:O10),"") -> 4 | AC10: =IF($AF10="Complete",AVERAGE(P10:T10),"") -> 4 | AD10: =IF($AF10="Complete",AVERAGE(U10:Y10),"") -> 4 | AE10: =IF($AF10="Complete",AVERAGE(Z10:AD10),"") -> 4 | AF10: =IF(COUNTA(B10:Y10)=0,"Not entered",IF(AND(COUNT(B10:Y10)=24,COUNTIF(B10:Y10,1)+COUNTIF(B10:Y10,2)+COUNTIF(B10:Y10,3)+COUNTIF(B10:Y10,4)=24),"Complete","CHECK PAPER")) -> Complete
A11: S10 | B11: 4 | C11: 4 | D11: 4 | E11: 4 | F11: 4 | G11: 4 | H11: 4 | I11: 4 | J11: 4 | K11: 4 | L11: 4 | M11: 4 | N11: 4 | O11: 4 | P11: 4 | Q11: 4 | R11: 4 | S11: 4 | T11: 4 | U11: 4 | V11: 4 | W11: 4 | X11: 4 | Y11: 4 | Z11: =IF($AF11="Complete",AVERAGE(B11:F11),"") -> 4 | AA11: =IF($AF11="Complete",AVERAGE(G11:J11),"") -> 4 | AB11: =IF($AF11="Complete",AVERAGE(K11:O11),"") -> 4 | AC11: =IF($AF11="Complete",AVERAGE(P11:T11),"") -> 4 | AD11: =IF($AF11="Complete",AVERAGE(U11:Y11),"") -> 4 | AE11: =IF($AF11="Complete",AVERAGE(Z11:AD11),"") -> 4 | AF11: =IF(COUNTA(B11:Y11)=0,"Not entered",IF(AND(COUNT(B11:Y11)=24,COUNTIF(B11:Y11,1)+COUNTIF(B11:Y11,2)+COUNTIF(B11:Y11,3)+COUNTIF(B11:Y11,4)=24),"Complete","CHECK PAPER")) -> Complete
A12: S11 | B12: 3 | C12: 4 | D12: 4 | E12: 3 | F12: 3 | G12: 4 | H12: 4 | I12: 4 | J12: 4 | K12: 4 | L12: 4 | M12: 4 | N12: 4 | O12: 4 | P12: 4 | Q12: 4 | R12: 4 | S12: 4 | T12: 4 | U12: 4 | V12: 4 | W12: 4 | X12: 4 | Y12: 4 | Z12: =IF($AF12="Complete",AVERAGE(B12:F12),"") -> 3.4 | AA12: =IF($AF12="Complete",AVERAGE(G12:J12),"") -> 4 | AB12: =IF($AF12="Complete",AVERAGE(K12:O12),"") -> 4 | AC12: =IF($AF12="Complete",AVERAGE(P12:T12),"") -> 4 | AD12: =IF($AF12="Complete",AVERAGE(U12:Y12),"") -> 4 | AE12: =IF($AF12="Complete",AVERAGE(Z12:AD12),"") -> 3.88 | AF12: =IF(COUNTA(B12:Y12)=0,"Not entered",IF(AND(COUNT(B12:Y12)=24,COUNTIF(B12:Y12,1)+COUNTIF(B12:Y12,2)+COUNTIF(B12:Y12,3)+COUNTIF(B12:Y12,4)=24),"Complete","CHECK PAPER")) -> Complete
A13: S12 | B13: 4 | C13: 4 | D13: 4 | E13: 4 | F13: 4 | G13: 4 | H13: 4 | I13: 4 | J13: 4 | K13: 4 | L13: 4 | M13: 4 | N13: 3 | O13: 4 | P13: 4 | Q13: 4 | R13: 4 | S13: 4 | T13: 4 | U13: 4 | V13: 4 | W13: 4 | X13: 4 | Y13: 4 | Z13: =IF($AF13="Complete",AVERAGE(B13:F13),"") -> 4 | AA13: =IF($AF13="Complete",AVERAGE(G13:J13),"") -> 4 | AB13: =IF($AF13="Complete",AVERAGE(K13:O13),"") -> 3.8 | AC13: =IF($AF13="Complete",AVERAGE(P13:T13),"") -> 4 | AD13: =IF($AF13="Complete",AVERAGE(U13:Y13),"") -> 4 | AE13: =IF($AF13="Complete",AVERAGE(Z13:AD13),"") -> 3.96 | AF13: =IF(COUNTA(B13:Y13)=0,"Not entered",IF(AND(COUNT(B13:Y13)=24,COUNTIF(B13:Y13,1)+COUNTIF(B13:Y13,2)+COUNTIF(B13:Y13,3)+COUNTIF(B13:Y13,4)=24),"Complete","CHECK PAPER")) -> Complete
... A71: S70 | B71: 4 | C71: 4 | D71: 2 | E71: 2 | F71: 4 | G71: 3 | H71: 3 | I71: 4 | J71: 4 | K71: 3 | L71: 3 | M71: 4 | N71: 4 | O71: 4 | P71: 3 | Q71: 4 | R71: 3 | S71: 4 | T71: 3 | U71: 3 | V71: 4 | W71: 3 | X71: 3 | Y71: 3 | Z71: =IF($AF71="Complete",AVERAGE(B71:F71),"") -> 3.2 | AA71: =IF($AF71="Complete",AVERAGE(G71:J71),"") -> 3.5 | AB71: =IF($AF71="Complete",AVERAGE(K71:O71),"") -> 3.6 | AC71: =IF($AF71="Complete",AVERAGE(P71:T71),"") -> 3.4 | AD71: =IF($AF71="Complete",AVERAGE(U71:Y71),"") -> 3.2 | AE71: =IF($AF71="Complete",AVERAGE(Z71:AD71),"") -> 3.38 | AF71: =IF(COUNTA(B71:Y71)=0,"Not entered",IF(AND(COUNT(B71:Y71)=24,COUNTIF(B71:Y71,1)+COUNTIF(B71:Y71,2)+COUNTIF(B71:Y71,3)+COUNTIF(B71:Y71,4)=24),"Complete","CHECK PAPER")) -> Complete
A74: System: enter one paper per row. Yellow answer cells accept whole numbers 1-4 only. Do not enter names or student IDs. | B74: System: enter one paper per row. Yellow answer cells accept whole numbers 1-4 only. Do not enter names or student IDs. | C74: System: enter one paper per row. Yellow answer cells accept whole numbers 1-4 only. Do not enter names or student IDs. | D74: System: enter one paper per row. Yellow answer cells accept whole numbers 1-4 only. Do not enter names or student IDs. | E74: System: enter one paper per row. Yellow answer cells accept whole numbers 1-4 only. Do not enter names or student IDs. | F74: System: enter one paper per row. Yellow answer cells accept whole numbers 1-4 only. Do not enter names or student IDs. | G74: System: enter one paper per row. Yellow answer cells accept whole numbers 1-4 only. Do not enter names or student IDs. | H74: System: enter one paper per row. Yellow answer cells accept whole numbers 1-4 only. Do not enter names or student IDs. | I74: System: enter one paper per row. Yellow answer cells accept whole numbers 1-4 only. Do not enter names or student IDs. | J74: System: enter one paper per row. Yellow answer cells accept whole numbers 1-4 only. Do not enter names or student IDs. | K74: System: enter one paper per row. Yellow answer cells accept whole numbers 1-4 only. Do not enter names or student IDs.
A75: Use the question key below to match section and item numbers. Leave missing or unclear answers blank; do not guess. | B75: Use the question key below to match section and item numbers. Leave missing or unclear answers blank; do not guess. | C75: Use the question key below to match section and item numbers. Leave missing or unclear answers blank; do not guess. | D75: Use the question key below to match section and item numbers. Leave missing or unclear answers blank; do not guess. | E75: Use the question key below to match section and item numbers. Leave missing or unclear answers blank; do not guess. | F75: Use the question key below to match section and item numbers. Leave missing or unclear answers blank; do not guess. | G75: Use the question key below to match section and item numbers. Leave missing or unclear answers blank; do not guess. | H75: Use the question key below to match section and item numbers. Leave missing or unclear answers blank; do not guess. | I75: Use the question key below to match section and item numbers. Leave missing or unclear answers blank; do not guess. | J75: Use the question key below to match section and item numbers. Leave missing or unclear answers blank; do not guess. | K75: Use the question key below to match section and item numbers. Leave missing or unclear answers blank; do not guess.
A77: Item code | B77: Question wording in the supplied tally | C77: Question wording in the supplied tally | D77: Question wording in the supplied tally | E77: Question wording in the supplied tally | F77: Question wording in the supplied tally | G77: Question wording in the supplied tally | H77: Question wording in the supplied tally | I77: Question wording in the supplied tally | J77: Question wording in the supplied tally | K77: Question wording in the supplied tally
A78: FS1 | B78: The system effectively meets the functional requirement of verifying my student identity using NFC, PIN, and QR codes. | C78: The system effectively meets the functional requirement of verifying my student identity using NFC, PIN, and QR codes. | D78: The system effectively meets the functional requirement of verifying my student identity using NFC, PIN, and QR codes. | E78: The system effectively meets the functional requirement of verifying my student identity using NFC, PIN, and QR codes. | F78: The system effectively meets the functional requirement of verifying my student identity using NFC, PIN, and QR codes. | G78: The system effectively meets the functional requirement of verifying my student identity using NFC, PIN, and QR codes. | H78: The system effectively meets the functional requirement of verifying my student identity using NFC, PIN, and QR codes. | I78: The system effectively meets the functional requirement of verifying my student identity using NFC, PIN, and QR codes. | J78: The system effectively meets the functional requirement of verifying my student identity using NFC, PIN, and QR codes. | K78: The system effectively meets the functional requirement of verifying my student identity using NFC, PIN, and QR codes.
A79: FS2 | B79: The system performs the attendance and entry verification tasks accurately and completely. | C79: The system performs the attendance and entry verification tasks accurately and completely. | D79: The system performs the attendance and entry verification tasks accurately and completely. | E79: The system performs the attendance and entry verification tasks accurately and completely. | F79: The system performs the attendance and entry verification tasks accurately and completely. | G79: The system performs the attendance and entry verification tasks accurately and completely. | H79: The system performs the attendance and entry verification tasks accurately and completely. | I79: The system performs the attendance and entry verification tasks accurately and completely. | J79: The system performs the attendance and entry verification tasks accurately and completely. | K79: The system performs the attendance and entry verification tasks accurately and completely.
A80: FS3 | B80: The features of the system are highly relevant to the problem of monitoring student attendance and campus entry. | C80: The features of the system are highly relevant to the problem of monitoring student attendance and campus entry. | D80: The features of the system are highly relevant to the problem of monitoring student attendance and campus entry. | E80: The features of the system are highly relevant to the problem of monitoring student attendance and campus entry. | F80: The features of the system are highly relevant to the problem of monitoring student attendance and campus entry. | G80: The features of the system are highly relevant to the problem of monitoring student attendance and campus entry. | H80: The features of the system are highly relevant to the problem of monitoring student attendance and campus entry. | I80: The features of the system are highly relevant to the problem of monitoring student attendance and campus entry. | J80: The features of the system are highly relevant to the problem of monitoring student attendance and campus entry. | K80: The features of the system are highly relevant to the problem of monitoring student attendance and campus entry.
A81: FS4 | B81: The system provides appropriate outputs (e.g., visual or audio confirmation) when I input my credentials. | C81: The system provides appropriate outputs (e.g., visual or audio confirmation) when I input my credentials. | D81: The system provides appropriate outputs (e.g., visual or audio confirmation) when I input my credentials. | E81: The system provides appropriate outputs (e.g., visual or audio confirmation) when I input my credentials. | F81: The system provides appropriate outputs (e.g., visual or audio confirmation) when I input my credentials. | G81: The system provides appropriate outputs (e.g., visual or audio confirmation) when I input my credentials. | H81: The system provides appropriate outputs (e.g., visual or audio confirmation) when I input my credentials. | I81: The system provides appropriate outputs (e.g., visual or audio confirmation) when I input my credentials. | J81: The system provides appropriate outputs (e.g., visual or audio confirmation) when I input my credentials. | K81: The system provides appropriate outputs (e.g., visual or audio confirmation) when I input my credentials.
A82: FS5 | B82: The overall functionality successfully aligns with the objective of providing a secure attendance system. | C82: The overall functionality successfully aligns with the objective of providing a secure attendance system. | D82: The overall functionality successfully aligns with the objective of providing a secure attendance system. | E82: The overall functionality successfully aligns with the objective of providing a secure attendance system. | F82: The overall functionality successfully aligns with the objective of providing a secure attendance system. | G82: The overall functionality successfully aligns with the objective of providing a secure attendance system. | H82: The overall functionality successfully aligns with the objective of providing a secure attendance system. | I82: The overall functionality successfully aligns with the objective of providing a secure attendance system. | J82: The overall functionality successfully aligns with the objective of providing a secure attendance system. | K82: The overall functionality successfully aligns with the objective of providing a secure attendance system.
A83: PE1 | B83: The system responds quickly when I tap my NFC card, enter my PIN, or scan my QR code. | C83: The system responds quickly when I tap my NFC card, enter my PIN, or scan my QR code. | D83: The system responds quickly when I tap my NFC card, enter my PIN, or scan my QR code. | E83: The system responds quickly when I tap my NFC card, enter my PIN, or scan my QR code. | F83: The system responds quickly when I tap my NFC card, enter my PIN, or scan my QR code. | G83: The system responds quickly when I tap my NFC card, enter my PIN, or scan my QR code. | H83: The system responds quickly when I tap my NFC card, enter my PIN, or scan my QR code. | I83: The system responds quickly when I tap my NFC card, enter my PIN, or scan my QR code. | J83: The system responds quickly when I tap my NFC card, enter my PIN, or scan my QR code. | K83: The system responds quickly when I tap my NFC card, enter my PIN, or scan my QR code.
